{"trial_id": "0012", "hyperparameters": {"space": [{"class_name": "Int", "config": {"name": "units", "default": null, "conditions": [], "min_value": 32, "max_value": 512, "step": 64, "sampling": "linear"}}, {"class_name": "Int", "config": {"name": "units_1", "default": null, "conditions": [], "min_value": 32, "max_value": 512, "step": 64, "sampling": "linear"}}, {"class_name": "Int", "config": {"name": "units_2", "default": null, "conditions": [], "min_value": 32, "max_value": 512, "step": 64, "sampling": "linear"}}], "values": {"units": 160, "tuner/epochs": 4, "tuner/initial_epoch": 2, "tuner/bracket": 2, "tuner/round": 1, "tuner/trial_id": "0005", "units_1": 480, "units_2": 160}}, "metrics": {"metrics": {}}, "score": null, "best_step": 0, "status": "FAILED", "message": "Traceback (most recent call last):\n  File \"c:\\Users\\e014694\\AppData\\Local\\Programs\\Python\\Python311\\Lib\\site-packages\\keras_tuner\\src\\engine\\base_tuner.py\", line 273, in _try_run_and_update_trial\n    self._run_and_update_trial(trial, *fit_args, **fit_kwargs)\n  File \"c:\\Users\\e014694\\AppData\\Local\\Programs\\Python\\Python311\\Lib\\site-packages\\keras_tuner\\src\\engine\\base_tuner.py\", line 238, in _run_and_update_trial\n    results = self.run_trial(trial, *fit_args, **fit_kwargs)\n              ^^^^^^^^^^^^^^^^^^^^^^^^^^^^^^^^^^^^^^^^^^^^^^\n  File \"c:\\Users\\e014694\\AppData\\Local\\Programs\\Python\\Python311\\Lib\\site-packages\\keras_tuner\\src\\tuners\\hyperband.py\", line 427, in run_trial\n    return super().run_trial(trial, *fit_args, **fit_kwargs)\n           ^^^^^^^^^^^^^^^^^^^^^^^^^^^^^^^^^^^^^^^^^^^^^^^^^\n  File \"c:\\Users\\e014694\\AppData\\Local\\Programs\\Python\\Python311\\Lib\\site-packages\\keras_tuner\\src\\engine\\tuner.py\", line 314, in run_trial\n    obj_value = self._build_and_fit_model(trial, *args, **copied_kwargs)\n                ^^^^^^^^^^^^^^^^^^^^^^^^^^^^^^^^^^^^^^^^^^^^^^^^^^^^^^^^\n  File \"c:\\Users\\e014694\\AppData\\Local\\Programs\\Python\\Python311\\Lib\\site-packages\\keras_tuner\\src\\engine\\tuner.py\", line 232, in _build_and_fit_model\n    model = self._try_build(hp)\n            ^^^^^^^^^^^^^^^^^^^\n  File \"c:\\Users\\e014694\\AppData\\Local\\Programs\\Python\\Python311\\Lib\\site-packages\\keras_tuner\\src\\engine\\tuner.py\", line 164, in _try_build\n    model = self._build_hypermodel(hp)\n            ^^^^^^^^^^^^^^^^^^^^^^^^^^\n  File \"c:\\Users\\e014694\\AppData\\Local\\Programs\\Python\\Python311\\Lib\\site-packages\\keras_tuner\\src\\tuners\\hyperband.py\", line 438, in _build_hypermodel\n    model.load_weights(self._get_checkpoint_fname(trial_id))\n  File \"c:\\Users\\e014694\\AppData\\Local\\Programs\\Python\\Python311\\Lib\\site-packages\\keras\\src\\utils\\traceback_utils.py\", line 70, in error_handler\n    raise e.with_traceback(filtered_tb) from None\n  File \"c:\\Users\\e014694\\AppData\\Local\\Programs\\Python\\Python311\\Lib\\site-packages\\tensorflow\\python\\ops\\resource_variable_ops.py\", line 760, in _restore_from_tensors\n    raise ValueError(\nValueError: Received incompatible tensor with shape (160,) when attempting to restore variable with shape (480,) and name dense_1/bias:0.\n"}